<mujoco>
  <option gravity="0 0 -9.81" density="1.204" viscosity="1.8e-5" integrator="implicit"/>

  <visual>
    <global elevation="-10"/>
    <headlight ambient="0.35 0.35 0.35" diffuse="0.65 0.65 0.65" specular="0.10 0.10 0.10"/>
  </visual>

  <default>
    <tendon limited="true" width="0.003" rgba="1 1 1 1"/>
    <geom friction=".2"/>
    <default class="weight">
      <geom rgba=".8 .4 .8 1"/>
      <site rgba=".8 .4 .8 1"/>
    </default>
    <default class="balloon">
      <geom density="0.167" fluidshape="ellipsoid"/>
      <default class="pink">
        <geom rgba="1 .6 .7 1"/>
        <site rgba="1 .6 .7 1"/>
      </default>
      <default class="blue">
        <geom rgba=".3 .7 .9 1"/>
        <site rgba=".3 .7 .9 1"/>
      </default>
      <default class="green">
        <geom rgba=".4 .9 .5 1"/>
        <site rgba=".4 .9 .5 1"/>
      </default>
      <default class="orange">
        <geom rgba="1 .4 0 1"/>
        <site rgba="1 .4 0 1"/>
      </default>
    </default>
  </default>

  <asset>
    <texture name="grid" type="2d" builtin="checker" width="512" height="512" rgb2="0.7 0.8 0.9" rgb1="0.4 0.5 0.6"/>
    <material name="grid" texture="grid" texrepeat="2 2" texuniform="true" reflectance=".6"/>
  </asset>

  <worldbody>
    <geom name="ground" type="plane" size="5 5 .05" pos="0 0 -.5" material="grid" solref="0.004 1" solimp="0.9 0.95 0.001" />
    <!-- <geom name="ramp" type="box" size=".4 .2 .03" pos="0 0 -.4" euler="0 20 0" rgba="1 1 1 1"/> -->
    
    <camera name="Above" pos="0 0 2" xyaxes="1 0 0 0 1 0"/>
    <camera name="Side" pos="0 -2 .2" xyaxes="1 0 0 0 .02 .97"/>

    <!-- シーン全体を照らす3点ライト -->
    <light name="sun_key" directional="true" diffuse="0.75 0.75 0.75" specular="0.20 0.20 0.20"
           pos="1 1 4" dir="-1 -1 -2" castshadow="true"/>
    <light name="sun_fill" directional="true" diffuse="0.45 0.45 0.45" specular="0.05 0.05 0.05"
           pos="-2 -1 3" dir="1 1 -1" castshadow="false"/>
    <light name="sun_rim" directional="true" diffuse="0.25 0.25 0.25" specular="0.05 0.05 0.05"
           pos="-1 2 2" dir="0 -1 -1" castshadow="false"/>

    <body name="board1" pos="0 0 1.0">
      <freejoint/>
      <geom type="box" size="1.0 0.4 0.05" mass="2" rgba="0.7 0.3 0.3 1"/>

      <body name="front_right_connection" pos="1.0 0.4 0">
        <joint name="front_right_leg" type="hinge" pos="0 0 0" damping="1.0" axis="0 1 0" />
        <geom type="cylinder" size="0.1 0.1" euler="90 0 0" mass="0.5"/>
        <body name="front_right_board" pos="0 0 -0.25">
          <geom type="box" size="0.02 0.1 0.2" mass="0.5" />
          <body name="front_right_connection2" pos = "0 0 -0.25">
            <joint name="front_right_leg2" type="hinge" pos="0 0 0" damping="1.0" axis="0 1 0" />
            <geom type="cylinder" size="0.1 0.1" euler="90 0 0" mass="0.5"/>
            <body name="front_right_board2" pos="0 0 -0.25">
              <geom type="box" size="0.02 0.1 0.2" mass="0.5" />
            </body>
          </body>
        </body>
      </body>

      <body name="front_left_connection" pos="1.0 -0.4 0">
        <joint name="front_left_leg" type="hinge" pos="0 0 0" damping="1.0" axis="0 1 0" />
        <geom type="cylinder" size="0.1 0.1" euler="90 0 0" mass="0.5"/>
        <body name="front_left_board" pos="0 0 -0.25">
          <geom type="box" size="0.02 0.1 0.2" mass="0.5" />
          <body name="front_left_connection2" pos = "0 0 -0.25">
            <joint name="front_left_leg2" type="hinge" pos="0 0 0" damping="1.0" axis="0 1 0" />
            <geom type="cylinder" size="0.1 0.1" euler="90 0 0" mass="0.5"/>
            <body name="front_left_board2" pos="0 0 -0.25">
              <geom type="box" size="0.02 0.1 0.2" mass="0.5" />
            </body>
          </body>
        </body>
      </body>

      <body name="back_right_connection" pos="-1.0 0.4 0">
        <joint name="back_right_leg" type="hinge" pos="0 0 0" damping="1.0" axis="0 1 0"/>
        <geom type="cylinder" size="0.1 0.1" euler="90 0 0" mass="0.5" />
        <body name="back_right_board" pos="0 0 -0.25">
          <geom type="box" size="0.02 0.1 0.2" mass="0.5" />
          <body name="back_right_connection2" pos = "0 0 -0.25">
            <joint name="back_right_leg2" type="hinge" pos="0 0 0" damping="1.0" axis="0 1 0" />
            <geom type="cylinder" size="0.1 0.1" euler="90 0 0" mass="0.5"/>
            <body name="back_right_board2" pos="0 0 -0.25">
              <geom type="box" size="0.02 0.1 0.2" mass="0.5" />
            </body>
          </body>
        </body>
      </body>

      <body name="back_left_connection" pos="-1.0 -0.4 0">
        <joint name="back_left_leg" type="hinge" pos="0 0 0" damping="1.0" axis="0 1 0"/>
        <geom type="cylinder" size="0.1 0.1" euler="90 0 0" mass="0.5" />
        <body name="back_left_board" pos="0 0 -0.25">
          <geom type="box" size="0.02 0.1 0.2" mass="0.5" />
          <body name="back_left_connection2" pos = "0 0 -0.25">
            <joint name="back_left_leg2" type="hinge" pos="0 0 0" damping="1.0" axis="0 1 0" />
            <geom type="cylinder" size="0.1 0.1" euler="90 0 0" mass="0.5"/>
            <body name="back_left_board2" pos="0 0 -0.25">
              <geom type="box" size="0.02 0.1 0.2" mass="0.5" />
            </body>
          </body>
        </body>
      </body>

    </body>
  </worldbody>

  <actuator>
    <position name="front_left_motor" joint="front_left_leg" kp="100"/>
    <position name="front_left_motor2" joint="front_left_leg2" kp="100"/>
    <position name="front_right_motor" joint="front_right_leg" kp="100"/>
    <position name="front_right_motor2" joint="front_right_leg2" kp="100"/>
    <position name="back_left_motor" joint="back_left_leg" kp="100"/>
    <position name="back_left_motor2" joint="back_left_leg2" kp="100"/>
    <position name="back_right_motor" joint="back_right_leg" kp="100"/>
    <position name="back_right_motor2" joint="back_right_leg2" kp="100"/>
  </actuator>
</mujoco>
